<?xml version="1.0" ?>
<mujoco>
    <option gravity="0 0 -9.81"/>
    <worldbody>
        <light diffuse=".5 .5 .5" pos="0 0 3" dir="0 0 -1"/>
        <geom type="plane" size="5 5 0.1" rgba=".9 .9 .9 1"/>
        <body pos="0 0 2">
            <joint type="hinge" axis="0 1 0" name="pendulum_joint"/>
            <geom type="capsule" size="0.1" fromto="0 0 0 0 0 1" rgba="1 0 0 1"/>
        </body>
    </worldbody>
    <actuator>
        <motor joint="pendulum_joint" name="torque" gear="1"/>
    </actuator>
</mujoco> 